<mujoco model="go2 house">
  <compiler angle="radian" meshdir="/home/yusen/Desktop/vector_os_nano/vector_os_nano/hardware/sim/mjcf/go2/assets/" texturedir="/home/yusen/Desktop/vector_os_nano/vector_os_nano/hardware/sim/mjcf/go2/assets/"/>

  <option impratio="100" cone="elliptic"/>

  <size nkey="1"/>

  <visual>
    <global azimuth="-120" elevation="-25" offwidth="1280" offheight="960"/>
    <quality shadowsize="1024"/>
    <headlight ambient="0.4 0.4 0.4" diffuse="0.5 0.5 0.5" specular="0 0 0"/>
    <map znear="0.05" shadowclip="0.5"/>
    <rgba haze="0.15 0.25 0.35 1"/>
  </visual>

  <statistic extent="12" center="10 7 0.5"/>

  <default>
    <default class="g1_main">
      <default class="g1_g1">
        <joint armature="0.01" frictionloss="0.3"/>
        <site size="0.01 0.005 0.005" group="5" rgba="1 0 0 1"/>
        <general biastype="affine" gainprm="500" biasprm="0 -500 1"/>
        <default class="g1_visual">
          <geom type="mesh" contype="0" conaffinity="0" group="2" density="0" material="metal"/>
        </default>
        <default class="g1_collision">
          <geom type="mesh" group="3"/>
          <default class="g1_foot">
            <geom size="0.005 0 0" type="sphere" priority="1" friction="0.6"/>
          </default>
        </default>
      </default>
    </default>
  </default>

  <asset>
    <texture type="skybox" colorspace="auto" builtin="gradient" rgb1="0.88 0.9 0.95" rgb2="0.65 0.7 0.8" width="512" height="3072"/>
    <texture type="2d" colorspace="auto" name="wall_tex" builtin="gradient" rgb1="0.94 0.93 0.91" rgb2="0.9 0.89 0.87" width="128" height="128"/>
    <texture type="2d" colorspace="auto" name="wood_tex" builtin="checker" rgb1="0.78 0.68 0.48" rgb2="0.74 0.64 0.45" width="200" height="200"/>
    <texture type="2d" colorspace="auto" name="tile_tex" builtin="checker" rgb1="0.9 0.9 0.88" rgb2="0.8 0.8 0.78" width="150" height="150"/>
    <texture type="2d" colorspace="auto" name="carpet_tex" builtin="flat" rgb1="0.5 0.52 0.56" rgb2="0.45 0.47 0.51" width="100" height="100"/>
    <texture type="2d" colorspace="auto" name="marble_tex" builtin="checker" rgb1="0.92 0.9 0.85" rgb2="0.85 0.82 0.77" width="120" height="120"/>
    <texture type="2d" colorspace="auto" name="bath_tex" builtin="checker" rgb1="0.85 0.9 0.92" rgb2="0.75 0.8 0.82" width="80" height="80"/>
    <texture type="2d" colorspace="sRGB" name="tex_oak" file="furniture/wood2.png"/>
    <texture type="2d" colorspace="linear" name="tex_walnut" file="furniture/wood1.png"/>
    <texture type="2d" colorspace="sRGB" name="tex_cherry" file="furniture/wood4.png"/>
    <texture type="2d" colorspace="sRGB" name="tex_pine" file="furniture/wood0.png"/>
    <texture type="2d" colorspace="linear" name="tex_steel" file="furniture/metal0.png"/>
    <texture type="2d" colorspace="linear" name="tex_chrome" file="furniture/metal1.png"/>
    <texture type="2d" colorspace="linear" name="tex_marble" file="furniture/stone0.png"/>
    <texture type="2d" colorspace="sRGB" name="tex_ceramic" file="furniture/stone1.png"/>
    <material name="wood_mat" texture="wood_tex" texuniform="true" texrepeat="10 10" reflectance="0.12"/>
    <material name="tile_mat" texture="tile_tex" texuniform="true" texrepeat="8 8" reflectance="0.25"/>
    <material name="carpet_mat" texture="carpet_tex" texuniform="true" texrepeat="3 3" reflectance="0.02"/>
    <material name="marble_mat" texture="marble_tex" texuniform="true" texrepeat="10 12" reflectance="0.2"/>
    <material name="bath_tile" texture="bath_tex" texuniform="true" texrepeat="6 6" reflectance="0.3"/>
    <material name="wall_mat" texture="wall_tex" texuniform="true" texrepeat="4 4" reflectance="0.04"/>
    <material name="accent_wall" reflectance="0.04" rgba="0.82 0.85 0.9 1"/>
    <material name="dark_wood" reflectance="0.12" rgba="0.35 0.22 0.12 1"/>
    <material name="rug_red" reflectance="0.02" rgba="0.6 0.15 0.12 1"/>
    <material name="rug_blue" reflectance="0.02" rgba="0.15 0.25 0.45 1"/>
    <material name="rug_beige" reflectance="0.02" rgba="0.82 0.75 0.62 1"/>
    <material name="painting_mat" reflectance="0.05" rgba="0.85 0.65 0.4 1"/>
    <material name="mat_oak" texture="tex_oak" texuniform="true" texrepeat="3 3" reflectance="0.12"/>
    <material name="mat_walnut" texture="tex_walnut" texuniform="true" texrepeat="3 3" reflectance="0.12"/>
    <material name="mat_cherry" texture="tex_cherry" texuniform="true" texrepeat="3 3" reflectance="0.1"/>
    <material name="mat_pine" texture="tex_pine" texuniform="true" texrepeat="4 4" reflectance="0.08"/>
    <material name="mat_steel" texture="tex_steel" texuniform="true" texrepeat="2 2" reflectance="0.4"/>
    <material name="mat_chrome" texture="tex_chrome" texuniform="true" texrepeat="2 2" reflectance="0.5"/>
    <material name="mat_marble" texture="tex_marble" texuniform="true" texrepeat="4 4" reflectance="0.25"/>
    <material name="mat_ceramic" texture="tex_ceramic" texuniform="true" texrepeat="3 3" reflectance="0.2"/>
    <material name="g1_black" rgba="0.2 0.2 0.2 1"/>
    <material name="g1_metal" rgba="0.7 0.7 0.7 1"/>
    <mesh name="m_loungeSofa_carpet" file="furniture/loungeSofa_carpet.obj" inertia="shell" scale="2.2 2.2 2.2"/>
    <mesh name="m_loungeSofa_wood" file="furniture/loungeSofa_wood.obj" inertia="shell" scale="2.2 2.2 2.2"/>
    <mesh name="m_coffee_table" file="furniture/tableCoffee.obj" inertia="shell" scale="1.8 1.8 1.8"/>
    <mesh name="m_tv_console" file="furniture/cabinetTelevision.obj" inertia="shell" scale="2 2 2"/>
    <mesh name="m_televisionModern_metalDark" file="furniture/televisionModern_metalDark.obj" inertia="shell" scale="1.7 1.7 1.7"/>
    <mesh name="m_televisionModern_metal" file="furniture/televisionModern_metal.obj" inertia="shell" scale="1.7 1.7 1.7"/>
    <mesh name="m_lampRoundFloor_metal" file="furniture/lampRoundFloor_metal.obj" inertia="shell" scale="1.7 1.7 1.7"/>
    <mesh name="m_lampRoundFloor_lamp" file="furniture/lampRoundFloor_lamp.obj" inertia="shell" scale="1.7 1.7 1.7"/>
    <mesh name="m_rugRectangle_carpet" file="furniture/rugRectangle_carpet.obj" inertia="shell" scale="2 2 2"/>
    <mesh name="m_rugRectangle_carpetDarker" file="furniture/rugRectangle_carpetDarker.obj" inertia="shell" scale="2 2 2"/>
    <mesh name="m_dining_table" file="furniture/table.obj" inertia="shell" scale="2 2 2"/>
    <mesh name="m_chair" file="furniture/chair.obj" inertia="shell" scale="2.1 2.1 2.1"/>
    <mesh name="m_sideTableDrawers_wood" file="furniture/sideTableDrawers_wood.obj" inertia="shell" scale="2 2 2"/>
    <mesh name="m_sideTableDrawers_defaultMat" file="furniture/sideTableDrawers_defaultMat.obj" inertia="shell" scale="2 2 2"/>
    <mesh name="m_sideTableDrawers_metal" file="furniture/sideTableDrawers_metal.obj" inertia="shell" scale="2 2 2"/>
    <mesh name="m_kitchenCabinetDrawer_metal" file="furniture/kitchenCabinetDrawer_metal.obj" inertia="shell" scale="2 2 2"/>
    <mesh name="m_kitchenCabinetDrawer_wood" file="furniture/kitchenCabinetDrawer_wood.obj" inertia="shell" scale="2 2 2"/>
    <mesh name="m_kitchenCabinetDrawer_woodDark" file="furniture/kitchenCabinetDrawer_woodDark.obj" inertia="shell" scale="2 2 2"/>
    <mesh name="m_kitchenStove_metal" file="furniture/kitchenStove_metal.obj" inertia="shell" scale="2 2 2"/>
    <mesh name="m_kitchenStove_wood" file="furniture/kitchenStove_wood.obj" inertia="shell" scale="2 2 2"/>
    <mesh name="m_kitchenStove_metalDark" file="furniture/kitchenStove_metalDark.obj" inertia="shell" scale="2 2 2"/>
    <mesh name="m_kitchenStove_carpetWhite" file="furniture/kitchenStove_carpetWhite.obj" inertia="shell" scale="2 2 2"/>
    <mesh name="m_kitchenStove_glass" file="furniture/kitchenStove_glass.obj" inertia="shell" scale="2 2 2"/>
    <mesh name="m_kitchenFridgeLarge_metalLight" file="furniture/kitchenFridgeLarge_metalLight.obj" inertia="shell" scale="1.9 1.9 1.9"/>
    <mesh name="m_kitchenFridgeLarge_metalMedium" file="furniture/kitchenFridgeLarge_metalMedium.obj" inertia="shell" scale="1.9 1.9 1.9"/>
    <mesh name="m_stoolBar_wood" file="furniture/stoolBar_wood.obj" inertia="shell" scale="1.8 1.8 1.8"/>
    <mesh name="m_stoolBar_carpet" file="furniture/stoolBar_carpet.obj" inertia="shell" scale="1.8 1.8 1.8"/>
    <mesh name="m_desk_wood" file="furniture/desk_wood.obj" inertia="shell" scale="2 2 2"/>
    <mesh name="m_desk_metal" file="furniture/desk_metal.obj" inertia="shell" scale="2 2 2"/>
    <mesh name="m_computerScreen_metalDark" file="furniture/computerScreen_metalDark.obj" inertia="shell" scale="1.6 1.6 1.6"/>
    <mesh name="m_computerScreen_metal" file="furniture/computerScreen_metal.obj" inertia="shell" scale="1.6 1.6 1.6"/>
    <mesh name="m_chairDesk_metalMedium" file="furniture/chairDesk_metalMedium.obj" inertia="shell" scale="1.7 1.7 1.7"/>
    <mesh name="m_chairDesk_carpet" file="furniture/chairDesk_carpet.obj" inertia="shell" scale="1.7 1.7 1.7"/>
    <mesh name="m_bookshelf" file="furniture/bookcaseOpen.obj" inertia="shell" scale="2 2 2"/>
    <mesh name="m_bedDouble_carpet" file="furniture/bedDouble_carpet.obj" inertia="shell" scale="2 2 2"/>
    <mesh name="m_bedDouble_carpetWhite" file="furniture/bedDouble_carpetWhite.obj" inertia="shell" scale="2 2 2"/>
    <mesh name="m_bedDouble_metal" file="furniture/bedDouble_metal.obj" inertia="shell" scale="2 2 2"/>
    <mesh name="m_bedDouble_wood" file="furniture/bedDouble_wood.obj" inertia="shell" scale="2 2 2"/>
    <mesh name="m_cabinetBedDrawer_wood" file="furniture/cabinetBedDrawer_wood.obj" inertia="shell" scale="1.9 1.9 1.9"/>
    <mesh name="m_cabinetBedDrawer_defaultMat" file="furniture/cabinetBedDrawer_defaultMat.obj" inertia="shell" scale="1.9 1.9 1.9"/>
    <mesh name="m_cabinetBedDrawer_metal" file="furniture/cabinetBedDrawer_metal.obj" inertia="shell" scale="1.9 1.9 1.9"/>
    <mesh name="m_bedSingle_carpet" file="furniture/bedSingle_carpet.obj" inertia="shell" scale="1.7 1.7 1.7"/>
    <mesh name="m_bedSingle_carpetWhite" file="furniture/bedSingle_carpetWhite.obj" inertia="shell" scale="1.7 1.7 1.7"/>
    <mesh name="m_bedSingle_metal" file="furniture/bedSingle_metal.obj" inertia="shell" scale="1.7 1.7 1.7"/>
    <mesh name="m_bedSingle_wood" file="furniture/bedSingle_wood.obj" inertia="shell" scale="1.7 1.7 1.7"/>
    <mesh name="m_dresser_wood" file="furniture/cabinetBedDrawerTable_wood.obj" inertia="shell" scale="1.9 1.9 1.9"/>
    <mesh name="m_dresser_defaultMat" file="furniture/cabinetBedDrawerTable_defaultMat.obj" inertia="shell" scale="1.9 1.9 1.9"/>
    <mesh name="m_dresser_metal" file="furniture/cabinetBedDrawerTable_metal.obj" inertia="shell" scale="1.9 1.9 1.9"/>
    <mesh name="m_bathtub_carpetWhite" file="furniture/bathtub_carpetWhite.obj" inertia="shell" scale="1.4 1.4 1.4"/>
    <mesh name="m_bathtub_metalLight" file="furniture/bathtub_metalLight.obj" inertia="shell" scale="1.4 1.4 1.4"/>
    <mesh name="m_bathtub_metalDark" file="furniture/bathtub_metalDark.obj" inertia="shell" scale="1.4 1.4 1.4"/>
    <mesh name="m_bathroomSink_defaultMat" file="furniture/bathroomSink_defaultMat.obj" inertia="shell" scale="1.5 1.5 1.5"/>
    <mesh name="m_bathroomSink_metalLight" file="furniture/bathroomSink_metalLight.obj" inertia="shell" scale="1.5 1.5 1.5"/>
    <mesh name="m_bathroomSink_carpetWhite" file="furniture/bathroomSink_carpetWhite.obj" inertia="shell" scale="1.5 1.5 1.5"/>
    <mesh name="m_washer_metalLight" file="furniture/washer_metalLight.obj" inertia="shell" scale="1.7 1.7 1.7"/>
    <mesh name="m_washer_metalMedium" file="furniture/washer_metalMedium.obj" inertia="shell" scale="1.7 1.7 1.7"/>
    <mesh name="m_washer_metalDark" file="furniture/washer_metalDark.obj" inertia="shell" scale="1.7 1.7 1.7"/>
    <mesh name="m_washer_metal" file="furniture/washer_metal.obj" inertia="shell" scale="1.7 1.7 1.7"/>
    <mesh name="m_washer_glass" file="furniture/washer_glass.obj" inertia="shell" scale="1.7 1.7 1.7"/>
    <mesh name="m_washer_defaultMat" file="furniture/washer_defaultMat.obj" inertia="shell" scale="1.7 1.7 1.7"/>
    <mesh name="m_dryer_metalLight" file="furniture/dryer_metalLight.obj" inertia="shell" scale="1.7 1.7 1.7"/>
    <mesh name="m_dryer_metalMedium" file="furniture/dryer_metalMedium.obj" inertia="shell" scale="1.7 1.7 1.7"/>
    <mesh name="m_dryer_metalDark" file="furniture/dryer_metalDark.obj" inertia="shell" scale="1.7 1.7 1.7"/>
    <mesh name="m_sideTable_wood" file="furniture/sideTable_wood.obj" inertia="shell" scale="1.8 1.8 1.8"/>
    <mesh name="m_sideTable_defaultMat" file="furniture/sideTable_defaultMat.obj" inertia="shell" scale="1.8 1.8 1.8"/>
    <mesh name="g1_pelvis" file="/home/yusen/Desktop/mujoco_menagerie/unitree_g1/assets/pelvis.STL"/>
    <mesh name="g1_pelvis_contour_link" file="/home/yusen/Desktop/mujoco_menagerie/unitree_g1/assets/pelvis_contour_link.STL"/>
    <mesh name="g1_left_hip_pitch_link" file="/home/yusen/Desktop/mujoco_menagerie/unitree_g1/assets/left_hip_pitch_link.STL"/>
    <mesh name="g1_left_hip_roll_link" file="/home/yusen/Desktop/mujoco_menagerie/unitree_g1/assets/left_hip_roll_link.STL"/>
    <mesh name="g1_left_hip_yaw_link" file="/home/yusen/Desktop/mujoco_menagerie/unitree_g1/assets/left_hip_yaw_link.STL"/>
    <mesh name="g1_left_knee_link" file="/home/yusen/Desktop/mujoco_menagerie/unitree_g1/assets/left_knee_link.STL"/>
    <mesh name="g1_left_ankle_pitch_link" file="/home/yusen/Desktop/mujoco_menagerie/unitree_g1/assets/left_ankle_pitch_link.STL"/>
    <mesh name="g1_left_ankle_roll_link" file="/home/yusen/Desktop/mujoco_menagerie/unitree_g1/assets/left_ankle_roll_link.STL"/>
    <mesh name="g1_right_hip_pitch_link" file="/home/yusen/Desktop/mujoco_menagerie/unitree_g1/assets/right_hip_pitch_link.STL"/>
    <mesh name="g1_right_hip_roll_link" file="/home/yusen/Desktop/mujoco_menagerie/unitree_g1/assets/right_hip_roll_link.STL"/>
    <mesh name="g1_right_hip_yaw_link" file="/home/yusen/Desktop/mujoco_menagerie/unitree_g1/assets/right_hip_yaw_link.STL"/>
    <mesh name="g1_right_knee_link" file="/home/yusen/Desktop/mujoco_menagerie/unitree_g1/assets/right_knee_link.STL"/>
    <mesh name="g1_right_ankle_pitch_link" file="/home/yusen/Desktop/mujoco_menagerie/unitree_g1/assets/right_ankle_pitch_link.STL"/>
    <mesh name="g1_right_ankle_roll_link" file="/home/yusen/Desktop/mujoco_menagerie/unitree_g1/assets/right_ankle_roll_link.STL"/>
    <mesh name="g1_waist_yaw_link" file="/home/yusen/Desktop/mujoco_menagerie/unitree_g1/assets/waist_yaw_link_rev_1_0.STL"/>
    <mesh name="g1_waist_roll_link" file="/home/yusen/Desktop/mujoco_menagerie/unitree_g1/assets/waist_roll_link_rev_1_0.STL"/>
    <mesh name="g1_torso_link" file="/home/yusen/Desktop/mujoco_menagerie/unitree_g1/assets/torso_link_rev_1_0.STL"/>
    <mesh name="g1_logo_link" file="/home/yusen/Desktop/mujoco_menagerie/unitree_g1/assets/logo_link.STL"/>
    <mesh name="g1_head_link" file="/home/yusen/Desktop/mujoco_menagerie/unitree_g1/assets/head_link.STL"/>
    <mesh name="g1_left_shoulder_pitch_link" file="/home/yusen/Desktop/mujoco_menagerie/unitree_g1/assets/left_shoulder_pitch_link.STL"/>
    <mesh name="g1_left_shoulder_roll_link" file="/home/yusen/Desktop/mujoco_menagerie/unitree_g1/assets/left_shoulder_roll_link.STL"/>
    <mesh name="g1_left_shoulder_yaw_link" file="/home/yusen/Desktop/mujoco_menagerie/unitree_g1/assets/left_shoulder_yaw_link.STL"/>
    <mesh name="g1_left_elbow_link" file="/home/yusen/Desktop/mujoco_menagerie/unitree_g1/assets/left_elbow_link.STL"/>
    <mesh name="g1_left_wrist_roll_link" file="/home/yusen/Desktop/mujoco_menagerie/unitree_g1/assets/left_wrist_roll_link.STL"/>
    <mesh name="g1_left_wrist_pitch_link" file="/home/yusen/Desktop/mujoco_menagerie/unitree_g1/assets/left_wrist_pitch_link.STL"/>
    <mesh name="g1_left_wrist_yaw_link" file="/home/yusen/Desktop/mujoco_menagerie/unitree_g1/assets/left_wrist_yaw_link.STL"/>
    <mesh name="g1_left_rubber_hand" file="/home/yusen/Desktop/mujoco_menagerie/unitree_g1/assets/left_rubber_hand.STL"/>
    <mesh name="g1_right_shoulder_pitch_link" file="/home/yusen/Desktop/mujoco_menagerie/unitree_g1/assets/right_shoulder_pitch_link.STL"/>
    <mesh name="g1_right_shoulder_roll_link" file="/home/yusen/Desktop/mujoco_menagerie/unitree_g1/assets/right_shoulder_roll_link.STL"/>
    <mesh name="g1_right_shoulder_yaw_link" file="/home/yusen/Desktop/mujoco_menagerie/unitree_g1/assets/right_shoulder_yaw_link.STL"/>
    <mesh name="g1_right_elbow_link" file="/home/yusen/Desktop/mujoco_menagerie/unitree_g1/assets/right_elbow_link.STL"/>
    <mesh name="g1_right_wrist_roll_link" file="/home/yusen/Desktop/mujoco_menagerie/unitree_g1/assets/right_wrist_roll_link.STL"/>
    <mesh name="g1_right_wrist_pitch_link" file="/home/yusen/Desktop/mujoco_menagerie/unitree_g1/assets/right_wrist_pitch_link.STL"/>
    <mesh name="g1_right_wrist_yaw_link" file="/home/yusen/Desktop/mujoco_menagerie/unitree_g1/assets/right_wrist_yaw_link.STL"/>
    <mesh name="g1_right_rubber_hand" file="/home/yusen/Desktop/mujoco_menagerie/unitree_g1/assets/right_rubber_hand.STL"/>
  </asset>

  <worldbody>
    <geom name="floor" size="10.5 7.5 0.05" pos="10 7 0" type="plane" material="marble_mat"/>
    <geom name="floor_raycast" size="10.5 7.5 0.01" pos="10 7 -0.02" type="box" contype="0" conaffinity="0" group="3" rgba="0 0 0 0"/>
    <geom name="ceiling" size="10.5 7.5 0.05" pos="10 7 2.85" type="box" contype="0" conaffinity="0" group="3" material="wall_mat"/>
    <geom name="f_living" size="3 2.5 0.001" pos="3 2.5 0.001" type="box" contype="0" conaffinity="0" material="wood_mat"/>
    <geom name="f_dining" size="3 2.5 0.001" pos="3 7.5 0.001" type="box" contype="0" conaffinity="0" material="wood_mat"/>
    <geom name="f_kitchen" size="3 2.5 0.001" pos="17 2.5 0.001" type="box" contype="0" conaffinity="0" material="tile_mat"/>
    <geom name="f_study" size="3 2.5 0.001" pos="17 7.5 0.001" type="box" contype="0" conaffinity="0" material="wood_mat"/>
    <geom name="f_master" size="3.5 2 0.001" pos="3.5 12 0.001" type="box" contype="0" conaffinity="0" material="carpet_mat"/>
    <geom name="f_guest" size="4 2 0.001" pos="16 12 0.001" type="box" contype="0" conaffinity="0" material="carpet_mat"/>
    <geom name="f_bath" size="1.5 2 0.001" pos="8.5 12 0.001" type="box" contype="0" conaffinity="0" material="bath_tile"/>
    <geom name="ew_south" size="10.1 0.05 1.4" pos="10 -0.05 1.4" type="box" material="wall_mat"/>
    <geom name="ew_north" size="10.1 0.05 1.4" pos="10 14.05 1.4" type="box" material="wall_mat"/>
    <geom name="ew_west" size="0.05 7.1 1.4" pos="-0.05 7 1.4" type="box" material="wall_mat"/>
    <geom name="ew_east" size="0.05 7.1 1.4" pos="20.05 7 1.4" type="box" material="wall_mat"/>
    <geom name="iw_l1" size="0.05 1.2 1.4" pos="6 1.2 1.4" type="box" material="accent_wall"/>
    <geom name="iw_l2" size="0.05 0.7 1.4" pos="6 4.3 1.4" type="box" material="accent_wall"/>
    <geom name="iw_l3" size="0.05 1.2 1.4" pos="6 6.2 1.4" type="box" material="accent_wall"/>
    <geom name="iw_l4" size="0.05 0.7 1.4" pos="6 9.3 1.4" type="box" material="accent_wall"/>
    <geom name="iw_r1" size="0.05 1.2 1.4" pos="14 1.2 1.4" type="box" material="accent_wall"/>
    <geom name="iw_r2" size="0.05 0.7 1.4" pos="14 4.3 1.4" type="box" material="accent_wall"/>
    <geom name="iw_r3" size="0.05 1.2 1.4" pos="14 6.2 1.4" type="box" material="accent_wall"/>
    <geom name="iw_r4" size="0.05 0.7 1.4" pos="14 9.3 1.4" type="box" material="accent_wall"/>
    <geom name="iw_ld1" size="1.2 0.05 1.4" pos="1.2 5 1.4" type="box" material="accent_wall"/>
    <geom name="iw_ld2" size="1.2 0.05 1.4" pos="4.8 5 1.4" type="box" material="accent_wall"/>
    <geom name="iw_ks1" size="1.2 0.05 1.4" pos="15.2 5 1.4" type="box" material="accent_wall"/>
    <geom name="iw_ks2" size="1.2 0.05 1.4" pos="18.8 5 1.4" type="box" material="accent_wall"/>
    <geom name="iw_b1" size="1.2 0.05 1.4" pos="1.2 10 1.4" type="box" material="wall_mat"/>
    <geom name="iw_b2" size="1.2 0.05 1.4" pos="4.8 10 1.4" type="box" material="wall_mat"/>
    <geom name="iw_b3" size="0.95 0.05 1.4" pos="6.95 10 1.4" type="box" material="wall_mat"/>
    <geom name="iw_b4" size="1.45 0.05 1.4" pos="10.55 10 1.4" type="box" material="wall_mat"/>
    <geom name="iw_b5" size="1 0.05 1.4" pos="13 10 1.4" type="box" material="wall_mat"/>
    <geom name="iw_b6" size="0.7 0.05 1.4" pos="14.7 10 1.4" type="box" material="wall_mat"/>
    <geom name="iw_b7" size="1.7 0.05 1.4" pos="18.3 10 1.4" type="box" material="wall_mat"/>
    <geom name="iw_bath_w" size="0.05 2.05 1.4" pos="7 12 1.4" type="box" material="wall_mat"/>
    <geom name="iw_laund_e" size="0.05 2.05 1.4" pos="12 12 1.4" type="box" material="wall_mat"/>
    <geom name="rug_living_carpet" pos="2 2 0.005" quat="0.707105 0.707108 0 0" type="mesh" contype="0" conaffinity="0" rgba="0.94 0.37 0.34 1" mesh="m_rugRectangle_carpet"/>
    <geom name="rug_living_darker" pos="2 2 0.005" quat="0.707105 0.707108 0 0" type="mesh" contype="0" conaffinity="0" rgba="0.61 0.3 0.29 1" mesh="m_rugRectangle_carpetDarker"/>
    <geom name="art_living" size="0.02 0.4 0.3" pos="0.02 2.5 1.5" type="box" contype="0" conaffinity="0" material="painting_mat"/>
    <geom name="rug_study_carpet" pos="17.5 7.5 0.005" quat="0.707105 0.707108 0 0" type="mesh" contype="0" conaffinity="0" rgba="0.94 0.37 0.34 1" mesh="m_rugRectangle_carpet"/>
    <geom name="rug_study_darker" pos="17.5 7.5 0.005" quat="0.707105 0.707108 0 0" type="mesh" contype="0" conaffinity="0" rgba="0.61 0.3 0.29 1" mesh="m_rugRectangle_carpetDarker"/>
    <geom name="rug_master_carpet" pos="3 12 0.005" quat="0.707105 0.707108 0 0" type="mesh" contype="0" conaffinity="0" rgba="0.94 0.37 0.34 1" mesh="m_rugRectangle_carpet"/>
    <geom name="rug_master_darker" pos="3 12 0.005" quat="0.707105 0.707108 0 0" type="mesh" contype="0" conaffinity="0" rgba="0.61 0.3 0.29 1" mesh="m_rugRectangle_carpetDarker"/>
    <geom name="rug_hall_carpet" pos="10 5 0.005" quat="0.499998 0.5 -0.500002 0.5" type="mesh" contype="0" conaffinity="0" rgba="0.94 0.37 0.34 1" mesh="m_rugRectangle_carpet"/>
    <geom name="rug_hall_darker" pos="10 5 0.005" quat="0.499998 0.5 -0.500002 0.5" type="mesh" contype="0" conaffinity="0" rgba="0.61 0.3 0.29 1" mesh="m_rugRectangle_carpetDarker"/>
    <geom name="art_hall1" size="0.015 0.35 0.25" pos="6.02 3 1.5" type="box" contype="0" conaffinity="0" material="painting_mat"/>
    <geom name="art_hall2" size="0.015 0.4 0.3" pos="13.98 6.5 1.5" type="box" contype="0" conaffinity="0" material="painting_mat"/>
    <geom name="bb_south" size="10 0.01 0.04" pos="10 0.06 0.04" type="box" contype="0" conaffinity="0" material="dark_wood"/>
    <geom name="bb_north" size="10 0.01 0.04" pos="10 13.94 0.04" type="box" contype="0" conaffinity="0" material="dark_wood"/>
    <geom name="bb_west" size="0.01 7 0.04" pos="0.06 7 0.04" type="box" contype="0" conaffinity="0" material="dark_wood"/>
    <geom name="bb_east" size="0.01 7 0.04" pos="19.94 7 0.04" type="box" contype="0" conaffinity="0" material="dark_wood"/>
    <geom name="df_living_l" size="0.06 0.03 1.1" pos="6 2.38 1.1" type="box" contype="0" conaffinity="0" material="dark_wood"/>
    <geom name="df_living_r" size="0.06 0.03 1.1" pos="6 3.62 1.1" type="box" contype="0" conaffinity="0" material="dark_wood"/>
    <geom name="df_living_t" size="0.06 0.62 0.03" pos="6 3 2.23" type="box" contype="0" conaffinity="0" material="dark_wood"/>
    <geom name="df_dining_l" size="0.06 0.03 1.1" pos="6 7.38 1.1" type="box" contype="0" conaffinity="0" material="dark_wood"/>
    <geom name="df_dining_r" size="0.06 0.03 1.1" pos="6 8.62 1.1" type="box" contype="0" conaffinity="0" material="dark_wood"/>
    <geom name="df_dining_t" size="0.06 0.62 0.03" pos="6 8 2.23" type="box" contype="0" conaffinity="0" material="dark_wood"/>
    <geom name="df_kitchen_l" size="0.06 0.03 1.1" pos="14 2.38 1.1" type="box" contype="0" conaffinity="0" material="dark_wood"/>
    <geom name="df_kitchen_r" size="0.06 0.03 1.1" pos="14 3.62 1.1" type="box" contype="0" conaffinity="0" material="dark_wood"/>
    <geom name="df_kitchen_t" size="0.06 0.62 0.03" pos="14 3 2.23" type="box" contype="0" conaffinity="0" material="dark_wood"/>
    <geom name="df_study_l" size="0.06 0.03 1.1" pos="14 7.38 1.1" type="box" contype="0" conaffinity="0" material="dark_wood"/>
    <geom name="df_study_r" size="0.06 0.03 1.1" pos="14 8.62 1.1" type="box" contype="0" conaffinity="0" material="dark_wood"/>
    <geom name="df_study_t" size="0.06 0.62 0.03" pos="14 8 2.23" type="box" contype="0" conaffinity="0" material="dark_wood"/>
    <geom name="df_ld_l" size="0.03 0.06 1.1" pos="2.38 5 1.1" type="box" contype="0" conaffinity="0" material="dark_wood"/>
    <geom name="df_ld_r" size="0.03 0.06 1.1" pos="3.62 5 1.1" type="box" contype="0" conaffinity="0" material="dark_wood"/>
    <geom name="df_ld_t" size="0.62 0.06 0.03" pos="3 5 2.23" type="box" contype="0" conaffinity="0" material="dark_wood"/>
    <geom name="df_ks_l" size="0.03 0.06 1.1" pos="16.38 5 1.1" type="box" contype="0" conaffinity="0" material="dark_wood"/>
    <geom name="df_ks_r" size="0.03 0.06 1.1" pos="17.62 5 1.1" type="box" contype="0" conaffinity="0" material="dark_wood"/>
    <geom name="df_ks_t" size="0.62 0.06 0.03" pos="17 5 2.23" type="box" contype="0" conaffinity="0" material="dark_wood"/>
    <geom name="df_master_l" size="0.03 0.06 1.1" pos="2.38 10 1.1" type="box" contype="0" conaffinity="0" material="dark_wood"/>
    <geom name="df_master_r" size="0.03 0.06 1.1" pos="3.62 10 1.1" type="box" contype="0" conaffinity="0" material="dark_wood"/>
    <geom name="df_master_t" size="0.62 0.06 0.03" pos="3 10 2.23" type="box" contype="0" conaffinity="0" material="dark_wood"/>
    <geom name="df_bath_l" size="0.03 0.06 1.1" pos="7.88 10 1.1" type="box" contype="0" conaffinity="0" material="dark_wood"/>
    <geom name="df_bath_r" size="0.03 0.06 1.1" pos="9.12 10 1.1" type="box" contype="0" conaffinity="0" material="dark_wood"/>
    <geom name="df_bath_t" size="0.62 0.06 0.03" pos="8.5 10 2.23" type="box" contype="0" conaffinity="0" material="dark_wood"/>
    <geom name="df_guest_l" size="0.03 0.06 1.1" pos="15.38 10 1.1" type="box" contype="0" conaffinity="0" material="dark_wood"/>
    <geom name="df_guest_r" size="0.03 0.06 1.1" pos="16.62 10 1.1" type="box" contype="0" conaffinity="0" material="dark_wood"/>
    <geom name="df_guest_t" size="0.62 0.06 0.03" pos="16 10 2.23" type="box" contype="0" conaffinity="0" material="dark_wood"/>
    <light name="light_living" pos="3 2.5 2.7" dir="0 0 -1" castshadow="false" cutoff="65" diffuse="0.55 0.5 0.42"/>
    <light name="light_dining" pos="3 7.5 2.7" dir="0 0 -1" castshadow="false" cutoff="65" diffuse="0.55 0.5 0.42"/>
    <light name="light_kitchen" pos="17 2.5 2.7" dir="0 0 -1" castshadow="false" cutoff="65" diffuse="0.6 0.58 0.52"/>
    <light name="light_study" pos="17 7.5 2.7" dir="0 0 -1" castshadow="false" cutoff="65" diffuse="0.55 0.52 0.45"/>
    <light name="light_hall_a" pos="10 3 2.7" dir="0 0 -1" castshadow="false" cutoff="55" diffuse="0.5 0.48 0.42"/>
    <light name="light_hall_b" pos="10 7 2.7" dir="0 0 -1" castshadow="false" cutoff="55" diffuse="0.5 0.48 0.42"/>
    <light name="light_master" pos="3.5 12 2.7" dir="0 0 -1" castshadow="false" cutoff="60" diffuse="0.5 0.45 0.38"/>
    <light name="light_guest" pos="16 12 2.7" dir="0 0 -1" castshadow="false" cutoff="60" diffuse="0.5 0.45 0.38"/>
    <light name="light_bath" pos="8.5 12 2.7" dir="0 0 -1" castshadow="false" cutoff="55" diffuse="0.55 0.55 0.55"/>
    <light name="sun" pos="10 7 4" dir="0 0 -1" type="directional" diffuse="0.35 0.35 0.35"/>
    <light name="fill_hall" pos="10 5 0.5" dir="0 0 1" castshadow="false" diffuse="0.15 0.14 0.12"/>
    <light name="fill_living" pos="3 2.5 0.5" dir="0 0 1" castshadow="false" diffuse="0.12 0.11 0.1"/>
    <light name="fill_dining" pos="3 7.5 0.5" dir="0 0 1" castshadow="false" diffuse="0.12 0.11 0.1"/>
    <light name="fill_kitchen" pos="17 2.5 0.5" dir="0 0 1" castshadow="false" diffuse="0.14 0.14 0.12"/>
    <body name="sofa_main" pos="1.8 1 0">
      <geom pos="1.08 0.45 0" quat="0.707105 0.707108 0 0" type="mesh" contype="0" conaffinity="0" rgba="0.94 0.37 0.34 1" mesh="m_loungeSofa_carpet"/>
      <geom pos="1.08 0.45 0" quat="0.707105 0.707108 0 0" type="mesh" contype="0" conaffinity="0" material="mat_walnut" mesh="m_loungeSofa_wood"/>
      <geom size="1.1 0.45 0.45" pos="0 0 0.45" type="box" group="3" rgba="0 0 0 0"/>
    </body>
    <body name="coffee_tbl" pos="1.8 2.3 0">
      <geom pos="-0.24 0.18 0" quat="0.707105 0.707108 0 0" type="mesh" contype="0" conaffinity="0" rgba="0.9 0.6 0.39 1" mesh="m_coffee_table"/>
      <geom size="0.6 0.35 0.2" pos="0 0 0.2" type="box" group="3" rgba="0 0 0 0"/>
    </body>
    <body name="tv_console" pos="0.5 3.5 0">
      <geom pos="0.8 0.25 0" quat="0.707105 0.707108 0 0" type="mesh" contype="0" conaffinity="0" rgba="0.9 0.6 0.39 1" mesh="m_tv_console"/>
      <geom size="0.8 0.25 0.3" pos="0 0 0.3" type="box" group="3" rgba="0 0 0 0"/>
    </body>
    <body name="tv_screen" pos="0.5 3.5 0.62">
      <geom pos="0 0 0" quat="0.707105 0.707108 0 0" type="mesh" contype="0" conaffinity="0" rgba="0.31 0.39 0.39 1" mesh="m_televisionModern_metalDark"/>
      <geom pos="0 0 0" quat="0.707105 0.707108 0 0" type="mesh" contype="0" conaffinity="0" rgba="0.74 0.82 0.84 1" mesh="m_televisionModern_metal"/>
    </body>
    <body name="lamp_living" pos="0.4 4.2 0">
      <geom pos="0.1 0.1 0" quat="0.707105 0.707108 0 0" type="mesh" contype="0" conaffinity="0" material="mat_chrome" mesh="m_lampRoundFloor_metal"/>
      <geom pos="0.1 0.1 0" quat="0.707105 0.707108 0 0" type="mesh" contype="0" conaffinity="0" rgba="1 0.91 0.59 1" mesh="m_lampRoundFloor_lamp"/>
      <geom size="0.12 0.7" pos="0 0 0.7" type="cylinder" group="3" rgba="0 0 0 0"/>
    </body>
    <body name="dining_table" pos="3 7.5 0">
      <geom pos="0.84 0.45 0" quat="0.707105 0.707108 0 0" type="mesh" contype="0" conaffinity="0" rgba="0.9 0.6 0.39 1" mesh="m_dining_table"/>
      <geom size="0.84 0.45 0.33" pos="0 0 0.33" type="box" group="3" rgba="0 0 0 0"/>
    </body>
    <body name="dchair1" pos="2 7.5 0">
      <geom pos="0.21 0.21 0" quat="0.707105 0.707108 0 0" type="mesh" contype="0" conaffinity="0" material="mat_oak" mesh="m_chair"/>
      <geom size="0.21 0.21 0.45" pos="0 0 0.45" type="box" group="3" rgba="0 0 0 0"/>
    </body>
    <body name="dchair2" pos="4 7.5 0">
      <geom pos="-0.21 -0.21 0" quat="-2.59734e-06 -2.59735e-06 -0.707108 0.707105" type="mesh" contype="0" conaffinity="0" material="mat_oak" mesh="m_chair"/>
      <geom size="0.21 0.21 0.45" pos="0 0 0.45" type="box" group="3" rgba="0 0 0 0"/>
    </body>
    <body name="dchair3" pos="3 6.7 0">
      <geom pos="0.21 -0.21 0" quat="0.499998 0.5 -0.500002 0.5" type="mesh" contype="0" conaffinity="0" material="mat_oak" mesh="m_chair"/>
      <geom size="0.21 0.21 0.45" pos="0 0 0.45" type="box" group="3" rgba="0 0 0 0"/>
    </body>
    <body name="dchair4" pos="3 8.3 0">
      <geom pos="-0.21 0.21 0" quat="0.499998 0.5 0.500002 -0.5" type="mesh" contype="0" conaffinity="0" material="mat_oak" mesh="m_chair"/>
      <geom size="0.21 0.21 0.45" pos="0 0 0.45" type="box" group="3" rgba="0 0 0 0"/>
    </body>
    <body name="sideboard" pos="0.5 8.5 0">
      <geom pos="0.51 0.2 0" quat="0.707105 0.707108 0 0" type="mesh" contype="0" conaffinity="0" material="mat_cherry" mesh="m_sideTableDrawers_wood"/>
      <geom pos="0.51 0.2 0" quat="0.707105 0.707108 0 0" type="mesh" contype="0" conaffinity="0" rgba="1 1 1 1" mesh="m_sideTableDrawers_defaultMat"/>
      <geom pos="0.51 0.2 0" quat="0.707105 0.707108 0 0" type="mesh" contype="0" conaffinity="0" rgba="0.74 0.82 0.84 1" mesh="m_sideTableDrawers_metal"/>
      <geom size="0.53 0.22 0.38" pos="0 0 0.38" type="box" group="3" rgba="0 0 0 0"/>
    </body>
    <body name="counter_east" pos="19.2 1 0">
      <geom pos="0.43 0.45 0" quat="0.707105 0.707108 0 0" type="mesh" contype="0" conaffinity="0" material="mat_chrome" mesh="m_kitchenCabinetDrawer_metal"/>
      <geom pos="0.43 0.45 0" quat="0.707105 0.707108 0 0" type="mesh" contype="0" conaffinity="0" material="mat_cherry" mesh="m_kitchenCabinetDrawer_wood"/>
      <geom pos="0.43 0.45 0" quat="0.707105 0.707108 0 0" type="mesh" contype="0" conaffinity="0" material="mat_walnut" mesh="m_kitchenCabinetDrawer_woodDark"/>
      <geom size="0.43 0.45 0.45" pos="0 0 0.45" type="box" group="3" rgba="0 0 0 0"/>
    </body>
    <body name="counter_east2" pos="19.2 2 0">
      <geom pos="0.43 0.45 0" quat="0.707105 0.707108 0 0" type="mesh" contype="0" conaffinity="0" material="mat_chrome" mesh="m_kitchenCabinetDrawer_metal"/>
      <geom pos="0.43 0.45 0" quat="0.707105 0.707108 0 0" type="mesh" contype="0" conaffinity="0" material="mat_cherry" mesh="m_kitchenCabinetDrawer_wood"/>
      <geom pos="0.43 0.45 0" quat="0.707105 0.707108 0 0" type="mesh" contype="0" conaffinity="0" material="mat_walnut" mesh="m_kitchenCabinetDrawer_woodDark"/>
      <geom size="0.43 0.45 0.45" pos="0 0 0.45" type="box" group="3" rgba="0 0 0 0"/>
    </body>
    <body name="counter_east3" pos="19.2 3 0">
      <geom pos="0.43 0.45 0" quat="0.707105 0.707108 0 0" type="mesh" contype="0" conaffinity="0" material="mat_chrome" mesh="m_kitchenCabinetDrawer_metal"/>
      <geom pos="0.43 0.45 0" quat="0.707105 0.707108 0 0" type="mesh" contype="0" conaffinity="0" material="mat_cherry" mesh="m_kitchenCabinetDrawer_wood"/>
      <geom pos="0.43 0.45 0" quat="0.707105 0.707108 0 0" type="mesh" contype="0" conaffinity="0" material="mat_walnut" mesh="m_kitchenCabinetDrawer_woodDark"/>
      <geom size="0.43 0.45 0.45" pos="0 0 0.45" type="box" group="3" rgba="0 0 0 0"/>
    </body>
    <body name="counter_south" pos="15.5 0.5 0">
      <geom pos="0.43 0.45 0" quat="0.707105 0.707108 0 0" type="mesh" contype="0" conaffinity="0" material="mat_steel" mesh="m_kitchenStove_metal"/>
      <geom pos="0.43 0.45 0" quat="0.707105 0.707108 0 0" type="mesh" contype="0" conaffinity="0" material="mat_cherry" mesh="m_kitchenStove_wood"/>
      <geom pos="0.43 0.45 0" quat="0.707105 0.707108 0 0" type="mesh" contype="0" conaffinity="0" rgba="0.31 0.39 0.39 1" mesh="m_kitchenStove_metalDark"/>
      <geom pos="0.43 0.45 0" quat="0.707105 0.707108 0 0" type="mesh" contype="0" conaffinity="0" rgba="0.97 1 1 1" mesh="m_kitchenStove_carpetWhite"/>
      <geom pos="0.43 0.45 0" quat="0.707105 0.707108 0 0" type="mesh" contype="0" conaffinity="0" rgba="0.7 0.83 0.77 1" mesh="m_kitchenStove_glass"/>
      <geom size="0.43 0.45 0.45" pos="0 0 0.45" type="box" group="3" rgba="0 0 0 0"/>
    </body>
    <body name="counter_south2" pos="16.5 0.5 0">
      <geom pos="0.43 0.45 0" quat="0.707105 0.707108 0 0" type="mesh" contype="0" conaffinity="0" material="mat_chrome" mesh="m_kitchenCabinetDrawer_metal"/>
      <geom pos="0.43 0.45 0" quat="0.707105 0.707108 0 0" type="mesh" contype="0" conaffinity="0" material="mat_cherry" mesh="m_kitchenCabinetDrawer_wood"/>
      <geom pos="0.43 0.45 0" quat="0.707105 0.707108 0 0" type="mesh" contype="0" conaffinity="0" material="mat_walnut" mesh="m_kitchenCabinetDrawer_woodDark"/>
      <geom size="0.43 0.45 0.45" pos="0 0 0.45" type="box" group="3" rgba="0 0 0 0"/>
    </body>
    <body name="island" pos="17 2.8 0">
      <geom pos="0.45 -0.43 0" quat="0.499998 0.5 -0.500002 0.5" type="mesh" contype="0" conaffinity="0" material="mat_chrome" mesh="m_kitchenCabinetDrawer_metal"/>
      <geom pos="0.45 -0.43 0" quat="0.499998 0.5 -0.500002 0.5" type="mesh" contype="0" conaffinity="0" material="mat_cherry" mesh="m_kitchenCabinetDrawer_wood"/>
      <geom pos="0.45 -0.43 0" quat="0.499998 0.5 -0.500002 0.5" type="mesh" contype="0" conaffinity="0" material="mat_walnut" mesh="m_kitchenCabinetDrawer_woodDark"/>
      <geom size="0.43 0.45 0.45" pos="0 0 0.45" type="box" group="3" rgba="0 0 0 0"/>
    </body>
    <body name="fridge" pos="19.2 4.3 0">
      <geom pos="0.49 0.26 0" quat="0.707105 0.707108 0 0" type="mesh" contype="0" conaffinity="0" material="mat_steel" mesh="m_kitchenFridgeLarge_metalLight"/>
      <geom pos="0.49 0.26 0" quat="0.707105 0.707108 0 0" type="mesh" contype="0" conaffinity="0" material="mat_chrome" mesh="m_kitchenFridgeLarge_metalMedium"/>
      <geom size="0.5 0.38 0.88" pos="0 0 0.88" type="box" group="3" rgba="0 0 0 0"/>
    </body>
    <body name="stool1" pos="16 2.8 0">
      <geom pos="0.24 0.21 0" quat="0.707105 0.707108 0 0" type="mesh" contype="0" conaffinity="0" material="mat_oak" mesh="m_stoolBar_wood"/>
      <geom pos="0.24 0.21 0" quat="0.707105 0.707108 0 0" type="mesh" contype="0" conaffinity="0" rgba="0.94 0.37 0.34 1" mesh="m_stoolBar_carpet"/>
      <geom size="0.17 0.38" pos="0 0 0.38" type="cylinder" group="3" rgba="0 0 0 0"/>
    </body>
    <body name="stool2" pos="18 2.8 0">
      <geom pos="0.24 0.21 0" quat="0.707105 0.707108 0 0" type="mesh" contype="0" conaffinity="0" material="mat_oak" mesh="m_stoolBar_wood"/>
      <geom pos="0.24 0.21 0" quat="0.707105 0.707108 0 0" type="mesh" contype="0" conaffinity="0" rgba="0.94 0.37 0.34 1" mesh="m_stoolBar_carpet"/>
      <geom size="0.17 0.38" pos="0 0 0.38" type="cylinder" group="3" rgba="0 0 0 0"/>
    </body>
    <body name="desk" pos="19 7.5 0">
      <geom pos="0.71 0.37 0" quat="0.707105 0.707108 0 0" type="mesh" contype="0" conaffinity="0" material="mat_walnut" mesh="m_desk_wood"/>
      <geom pos="0.71 0.37 0" quat="0.707105 0.707108 0 0" type="mesh" contype="0" conaffinity="0" material="mat_chrome" mesh="m_desk_metal"/>
      <geom size="0.73 0.39 0.38" pos="0 0 0.38" type="box" group="3" rgba="0 0 0 0"/>
    </body>
    <body name="monitor" pos="19 7.5 0.77">
      <geom pos="0.31 0.08 0" quat="0.707105 0.707108 0 0" type="mesh" contype="0" conaffinity="0" rgba="0.31 0.39 0.39 1" mesh="m_computerScreen_metalDark"/>
      <geom pos="0.31 0.08 0" quat="0.707105 0.707108 0 0" type="mesh" contype="0" conaffinity="0" rgba="0.74 0.82 0.84 1" mesh="m_computerScreen_metal"/>
    </body>
    <body name="desk_chair" pos="18 7.5 0">
      <geom pos="0.28 0.27 0" quat="0.707105 0.707108 0 0" type="mesh" contype="0" conaffinity="0" material="mat_chrome" mesh="m_chairDesk_metalMedium"/>
      <geom pos="0.28 0.27 0" quat="0.707105 0.707108 0 0" type="mesh" contype="0" conaffinity="0" rgba="0.94 0.37 0.34 1" mesh="m_chairDesk_carpet"/>
      <geom size="0.28 0.27 0.5" pos="0 0 0.5" type="box" group="3" rgba="0 0 0 0"/>
    </body>
    <body name="bookshelf" pos="17 5.3 0">
      <geom pos="0.4 0.25 0" quat="0.707105 0.707108 0 0" type="mesh" contype="0" conaffinity="0" rgba="0.9 0.6 0.39 1" mesh="m_bookshelf"/>
      <geom size="0.4 0.25 0.88" pos="0 0 0.88" type="box" group="3" rgba="0 0 0 0"/>
    </body>
    <body name="master_bed" pos="1.5 12 0">
      <geom pos="0.96 1.12 0" quat="0.707105 0.707108 0 0" type="mesh" contype="0" conaffinity="0" rgba="0.94 0.37 0.34 1" mesh="m_bedDouble_carpet"/>
      <geom pos="0.96 1.12 0" quat="0.707105 0.707108 0 0" type="mesh" contype="0" conaffinity="0" rgba="0.97 1 1 1" mesh="m_bedDouble_carpetWhite"/>
      <geom pos="0.96 1.12 0" quat="0.707105 0.707108 0 0" type="mesh" contype="0" conaffinity="0" material="mat_chrome" mesh="m_bedDouble_metal"/>
      <geom pos="0.96 1.12 0" quat="0.707105 0.707108 0 0" type="mesh" contype="0" conaffinity="0" material="mat_walnut" mesh="m_bedDouble_wood"/>
      <geom size="0.96 1.12 0.35" pos="0 0 0.35" type="box" group="3" rgba="0 0 0 0"/>
    </body>
    <body name="nightstand_l" pos="1.5 10.6 0">
      <geom pos="0.23 0.18 0" quat="0.707105 0.707108 0 0" type="mesh" contype="0" conaffinity="0" material="mat_walnut" mesh="m_cabinetBedDrawer_wood"/>
      <geom pos="0.23 0.18 0" quat="0.707105 0.707108 0 0" type="mesh" contype="0" conaffinity="0" rgba="1 1 1 1" mesh="m_cabinetBedDrawer_defaultMat"/>
      <geom pos="0.23 0.18 0" quat="0.707105 0.707108 0 0" type="mesh" contype="0" conaffinity="0" material="mat_chrome" mesh="m_cabinetBedDrawer_metal"/>
      <geom size="0.25 0.2 0.25" pos="0 0 0.25" type="box" group="3" rgba="0 0 0 0"/>
    </body>
    <body name="nightstand_r" pos="1.5 13.4 0">
      <geom pos="0.23 0.18 0" quat="0.707105 0.707108 0 0" type="mesh" contype="0" conaffinity="0" material="mat_walnut" mesh="m_cabinetBedDrawer_wood"/>
      <geom pos="0.23 0.18 0" quat="0.707105 0.707108 0 0" type="mesh" contype="0" conaffinity="0" rgba="1 1 1 1" mesh="m_cabinetBedDrawer_defaultMat"/>
      <geom pos="0.23 0.18 0" quat="0.707105 0.707108 0 0" type="mesh" contype="0" conaffinity="0" material="mat_chrome" mesh="m_cabinetBedDrawer_metal"/>
      <geom size="0.25 0.2 0.25" pos="0 0 0.25" type="box" group="3" rgba="0 0 0 0"/>
    </body>
    <body name="wardrobe" pos="5.5 13.3 0">
      <geom pos="0.4 0.25 0" quat="0.707105 0.707108 0 0" type="mesh" contype="0" conaffinity="0" rgba="0.9 0.6 0.39 1" mesh="m_bookshelf"/>
      <geom size="0.4 0.3 0.88" pos="0 0 0.88" type="box" group="3" rgba="0 0 0 0"/>
    </body>
    <body name="guest_bed" pos="17.5 12 0">
      <geom pos="1.14 0.96 0" quat="0.707105 0.707108 0 0" type="mesh" contype="0" conaffinity="0" rgba="0.94 0.37 0.34 1" mesh="m_bedSingle_carpet"/>
      <geom pos="1.14 0.96 0" quat="0.707105 0.707108 0 0" type="mesh" contype="0" conaffinity="0" rgba="0.97 1 1 1" mesh="m_bedSingle_carpetWhite"/>
      <geom pos="1.14 0.96 0" quat="0.707105 0.707108 0 0" type="mesh" contype="0" conaffinity="0" material="mat_chrome" mesh="m_bedSingle_metal"/>
      <geom pos="1.14 0.96 0" quat="0.707105 0.707108 0 0" type="mesh" contype="0" conaffinity="0" material="mat_oak" mesh="m_bedSingle_wood"/>
      <geom size="0.5 0.96 0.32" pos="0 0 0.32" type="box" group="3" rgba="0 0 0 0"/>
    </body>
    <body name="guest_nightstand" pos="16.3 12.5 0">
      <geom pos="0.23 0.18 0" quat="0.707105 0.707108 0 0" type="mesh" contype="0" conaffinity="0" material="mat_walnut" mesh="m_cabinetBedDrawer_wood"/>
      <geom pos="0.23 0.18 0" quat="0.707105 0.707108 0 0" type="mesh" contype="0" conaffinity="0" rgba="1 1 1 1" mesh="m_cabinetBedDrawer_defaultMat"/>
      <geom pos="0.23 0.18 0" quat="0.707105 0.707108 0 0" type="mesh" contype="0" conaffinity="0" material="mat_chrome" mesh="m_cabinetBedDrawer_metal"/>
      <geom size="0.25 0.2 0.25" pos="0 0 0.25" type="box" group="3" rgba="0 0 0 0"/>
    </body>
    <body name="dresser" pos="13 13.3 0">
      <geom pos="0.23 0.18 0" quat="0.707105 0.707108 0 0" type="mesh" contype="0" conaffinity="0" rgba="0.9 0.6 0.39 1" mesh="m_dresser_wood"/>
      <geom pos="0.23 0.18 0" quat="0.707105 0.707108 0 0" type="mesh" contype="0" conaffinity="0" rgba="1 1 1 1" mesh="m_dresser_defaultMat"/>
      <geom pos="0.23 0.18 0" quat="0.707105 0.707108 0 0" type="mesh" contype="0" conaffinity="0" rgba="0.74 0.82 0.84 1" mesh="m_dresser_metal"/>
      <geom size="0.25 0.2 0.25" pos="0 0 0.25" type="box" group="3" rgba="0 0 0 0"/>
    </body>
    <body name="bathtub" pos="8.5 13.2 0">
      <geom pos="0.83 0.39 0" quat="0.707105 0.707108 0 0" type="mesh" contype="0" conaffinity="0" material="mat_ceramic" mesh="m_bathtub_carpetWhite"/>
      <geom pos="0.83 0.39 0" quat="0.707105 0.707108 0 0" type="mesh" contype="0" conaffinity="0" material="mat_ceramic" mesh="m_bathtub_metalLight"/>
      <geom pos="0.83 0.39 0" quat="0.707105 0.707108 0 0" type="mesh" contype="0" conaffinity="0" rgba="0.31 0.39 0.39 1" mesh="m_bathtub_metalDark"/>
      <geom size="0.83 0.39 0.3" pos="0 0 0.3" type="box" group="3" rgba="0 0 0 0"/>
    </body>
    <body name="vanity" pos="7.5 11 0">
      <geom pos="0.26 0.22 0" quat="0.707105 0.707108 0 0" type="mesh" contype="0" conaffinity="0" material="mat_ceramic" mesh="m_bathroomSink_defaultMat"/>
      <geom pos="0.26 0.22 0" quat="0.707105 0.707108 0 0" type="mesh" contype="0" conaffinity="0" material="mat_chrome" mesh="m_bathroomSink_metalLight"/>
      <geom pos="0.26 0.22 0" quat="0.707105 0.707108 0 0" type="mesh" contype="0" conaffinity="0" material="mat_ceramic" mesh="m_bathroomSink_carpetWhite"/>
      <geom size="0.26 0.22 0.42" pos="0 0 0.42" type="box" group="3" rgba="0 0 0 0"/>
    </body>
    <body name="washer" pos="11 11 0">
      <geom pos="0.33 0.26 0" quat="0.707105 0.707108 0 0" type="mesh" contype="0" conaffinity="0" material="mat_steel" mesh="m_washer_metalLight"/>
      <geom pos="0.33 0.26 0" quat="0.707105 0.707108 0 0" type="mesh" contype="0" conaffinity="0" material="mat_chrome" mesh="m_washer_metalMedium"/>
      <geom pos="0.33 0.26 0" quat="0.707105 0.707108 0 0" type="mesh" contype="0" conaffinity="0" rgba="0.31 0.39 0.39 1" mesh="m_washer_metalDark"/>
      <geom pos="0.33 0.26 0" quat="0.707105 0.707108 0 0" type="mesh" contype="0" conaffinity="0" material="mat_chrome" mesh="m_washer_metal"/>
      <geom pos="0.33 0.26 0" quat="0.707105 0.707108 0 0" type="mesh" contype="0" conaffinity="0" rgba="0.7 0.83 0.77 1" mesh="m_washer_glass"/>
      <geom pos="0.33 0.26 0" quat="0.707105 0.707108 0 0" type="mesh" contype="0" conaffinity="0" rgba="1 1 1 1" mesh="m_washer_defaultMat"/>
      <geom size="0.33 0.33 0.4" pos="0 0 0.4" type="box" group="3" rgba="0 0 0 0"/>
    </body>
    <body name="dryer_unit" pos="11 12 0">
      <geom pos="0.33 0.27 0" quat="0.707105 0.707108 0 0" type="mesh" contype="0" conaffinity="0" material="mat_steel" mesh="m_dryer_metalLight"/>
      <geom pos="0.33 0.27 0" quat="0.707105 0.707108 0 0" type="mesh" contype="0" conaffinity="0" material="mat_chrome" mesh="m_dryer_metalMedium"/>
      <geom pos="0.33 0.27 0" quat="0.707105 0.707108 0 0" type="mesh" contype="0" conaffinity="0" rgba="0.31 0.39 0.39 1" mesh="m_dryer_metalDark"/>
      <geom size="0.33 0.33 0.4" pos="0 0 0.4" type="box" group="3" rgba="0 0 0 0"/>
    </body>
    <body name="console_table" pos="6.5 5 0">
      <geom pos="0.46 0.18 0" quat="0.707105 0.707108 0 0" type="mesh" contype="0" conaffinity="0" material="mat_cherry" mesh="m_sideTable_wood"/>
      <geom pos="0.46 0.18 0" quat="0.707105 0.707108 0 0" type="mesh" contype="0" conaffinity="0" rgba="1 1 1 1" mesh="m_sideTable_defaultMat"/>
      <geom size="0.48 0.2 0.35" pos="0 0 0.35" type="box" group="3" rgba="0 0 0 0"/>
    </body>
    <body name="pick_table" pos="10.95 3 0">
      <geom size="0.15 0.25 0.14" pos="0 0 0.14" type="box" material="mat_oak"/>
    </body>
    <body name="pickable_bottle_blue" pos="10.9 2.78 0.32">
      <joint type="free"/>
      <geom size="0.028 0.04" type="cylinder" priority="2" friction="2 0.05 0.001" mass="0.08" rgba="0.2 0.4 0.85 1"/>
    </body>
    <body name="pickable_bottle_green" pos="10.88 3 0.32">
      <joint type="free"/>
      <geom size="0.028 0.04" type="cylinder" priority="2" friction="2 0.05 0.001" mass="0.08" rgba="0.25 0.7 0.35 1"/>
    </body>
    <body name="pickable_can_red" pos="10.9 3.22 0.32">
      <joint type="free"/>
      <geom size="0.033 0.04" type="cylinder" priority="2" friction="2 0.05 0.001" mass="0.08" rgba="0.85 0.25 0.2 1"/>
    </body>
    <light pos="11 3 3.5" dir="0 0 -1" type="directional"/>
    <body name="g1_pelvis" childclass="g1_g1" pos="10 3 0.793">
      <inertial pos="0 0 -0.07605" quat="1 0 -0.000399148 0" mass="3.813" diaginertia="0.010549 0.0093089 0.0079184"/>
      <joint name="g1_floating_base_joint" type="free" armature="0" frictionloss="0"/>
      <geom class="g1_visual" material="g1_black" mesh="g1_pelvis"/>
      <geom class="g1_visual" material="g1_metal" mesh="g1_pelvis_contour_link"/>
      <geom class="g1_collision" mesh="g1_pelvis_contour_link"/>
      <site name="g1_imu_in_pelvis" pos="0.04525 0 -0.08339"/>
      <body name="g1_left_hip_pitch_link" pos="0 0.064452 -0.1027">
        <inertial pos="0.002741 0.047791 -0.02606" quat="0.954862 0.293964 0.0302556 0.030122" mass="1.35" diaginertia="0.00181517 0.00153422 0.00116212"/>
        <joint name="g1_left_hip_pitch_joint" pos="0 0 0" axis="0 1 0" range="-2.5307 2.8798" actuatorfrcrange="-88 88"/>
        <geom class="g1_visual" material="g1_black" mesh="g1_left_hip_pitch_link"/>
        <geom class="g1_collision" material="g1_black" mesh="g1_left_hip_pitch_link"/>
        <body name="g1_left_hip_roll_link" pos="0 0.052 -0.030465" quat="0.996179 0 -0.0873386 0">
          <inertial pos="0.029812 -0.001045 -0.087934" quat="0.977808 -1.97119e-05 0.205576 -0.0403793" mass="1.52" diaginertia="0.00254986 0.00241169 0.00148755"/>
          <joint name="g1_left_hip_roll_joint" pos="0 0 0" axis="1 0 0" range="-0.5236 2.9671" actuatorfrcrange="-139 139"/>
          <geom class="g1_visual" material="g1_metal" mesh="g1_left_hip_roll_link"/>
          <geom class="g1_collision" mesh="g1_left_hip_roll_link"/>
          <body name="g1_left_hip_yaw_link" pos="0.025001 0 -0.12412">
            <inertial pos="-0.057709 -0.010981 -0.15078" quat="0.600598 0.15832 0.223482 0.751181" mass="1.702" diaginertia="0.00776166 0.00717575 0.00160139"/>
            <joint name="g1_left_hip_yaw_joint" pos="0 0 0" axis="0 0 1" range="-2.7576 2.7576" actuatorfrcrange="-88 88"/>
            <geom class="g1_visual" material="g1_metal" mesh="g1_left_hip_yaw_link"/>
            <geom class="g1_collision" mesh="g1_left_hip_yaw_link"/>
            <body name="g1_left_knee_link" pos="-0.078273 0.0021489 -0.17734" quat="0.996179 0 0.0873386 0">
              <inertial pos="0.005457 0.003964 -0.12074" quat="0.923418 -0.0327699 0.0158246 0.382067" mass="1.932" diaginertia="0.0113804 0.0112778 0.00146458"/>
              <joint name="g1_left_knee_joint" pos="0 0 0" axis="0 1 0" range="-0.087267 2.8798" actuatorfrcrange="-139 139"/>
              <geom class="g1_visual" material="g1_metal" mesh="g1_left_knee_link"/>
              <geom class="g1_collision" mesh="g1_left_knee_link"/>
              <body name="g1_left_ankle_pitch_link" pos="0 -9.4445e-05 -0.30001">
                <inertial pos="-0.007269 0 0.011137" quat="0.603053 0.369225 0.369225 0.603053" mass="0.074" diaginertia="1.89e-05 1.40805e-05 6.9195e-06"/>
                <joint name="g1_left_ankle_pitch_joint" pos="0 0 0" axis="0 1 0" range="-0.87267 0.5236" actuatorfrcrange="-50 50"/>
                <geom class="g1_visual" material="g1_metal" mesh="g1_left_ankle_pitch_link"/>
                <geom class="g1_collision" mesh="g1_left_ankle_pitch_link"/>
                <body name="g1_left_ankle_roll_link" pos="0 0 -0.017558">
                  <inertial pos="0.026505 0 -0.016425" quat="-0.000481092 0.728482 -0.000618967 0.685065" mass="0.608" diaginertia="0.00167218 0.0016161 0.000217621"/>
                  <joint name="g1_left_ankle_roll_joint" pos="0 0 0" axis="1 0 0" range="-0.2618 0.2618" actuatorfrcrange="-50 50"/>
                  <geom class="g1_visual" material="g1_black" mesh="g1_left_ankle_roll_link"/>
                  <geom class="g1_foot" pos="-0.05 0.025 -0.03"/>
                  <geom class="g1_foot" pos="-0.05 -0.025 -0.03"/>
                  <geom class="g1_foot" pos="0.12 0.03 -0.03"/>
                  <geom class="g1_foot" pos="0.12 -0.03 -0.03"/>
                  <site name="g1_left_foot" pos="0 0 0"/>
                </body>
              </body>
            </body>
          </body>
        </body>
      </body>
      <body name="g1_right_hip_pitch_link" pos="0 -0.064452 -0.1027">
        <inertial pos="0.002741 -0.047791 -0.02606" quat="0.954862 -0.293964 0.0302556 -0.030122" mass="1.35" diaginertia="0.00181517 0.00153422 0.00116212"/>
        <joint name="g1_right_hip_pitch_joint" pos="0 0 0" axis="0 1 0" range="-2.5307 2.8798" actuatorfrcrange="-88 88"/>
        <geom class="g1_visual" material="g1_black" mesh="g1_right_hip_pitch_link"/>
        <geom class="g1_collision" material="g1_black" mesh="g1_right_hip_pitch_link"/>
        <body name="g1_right_hip_roll_link" pos="0 -0.052 -0.030465" quat="0.996179 0 -0.0873386 0">
          <inertial pos="0.029812 0.001045 -0.087934" quat="0.977808 1.97119e-05 0.205576 0.0403793" mass="1.52" diaginertia="0.00254986 0.00241169 0.00148755"/>
          <joint name="g1_right_hip_roll_joint" pos="0 0 0" axis="1 0 0" range="-2.9671 0.5236" actuatorfrcrange="-139 139"/>
          <geom class="g1_visual" material="g1_metal" mesh="g1_right_hip_roll_link"/>
          <geom class="g1_collision" mesh="g1_right_hip_roll_link"/>
          <body name="g1_right_hip_yaw_link" pos="0.025001 0 -0.12412">
            <inertial pos="-0.057709 0.010981 -0.15078" quat="0.751181 0.223482 0.15832 0.600598" mass="1.702" diaginertia="0.00776166 0.00717575 0.00160139"/>
            <joint name="g1_right_hip_yaw_joint" pos="0 0 0" axis="0 0 1" range="-2.7576 2.7576" actuatorfrcrange="-88 88"/>
            <geom class="g1_visual" material="g1_metal" mesh="g1_right_hip_yaw_link"/>
            <geom class="g1_collision" mesh="g1_right_hip_yaw_link"/>
            <body name="g1_right_knee_link" pos="-0.078273 -0.0021489 -0.17734" quat="0.996179 0 0.0873386 0">
              <inertial pos="0.005457 -0.003964 -0.12074" quat="0.923439 0.0345276 0.0116333 -0.382012" mass="1.932" diaginertia="0.011374 0.0112843 0.00146452"/>
              <joint name="g1_right_knee_joint" pos="0 0 0" axis="0 1 0" range="-0.087267 2.8798" actuatorfrcrange="-139 139"/>
              <geom class="g1_visual" material="g1_metal" mesh="g1_right_knee_link"/>
              <geom class="g1_collision" mesh="g1_right_knee_link"/>
              <body name="g1_right_ankle_pitch_link" pos="0 9.4445e-05 -0.30001">
                <inertial pos="-0.007269 0 0.011137" quat="0.603053 0.369225 0.369225 0.603053" mass="0.074" diaginertia="1.89e-05 1.40805e-05 6.9195e-06"/>
                <joint name="g1_right_ankle_pitch_joint" pos="0 0 0" axis="0 1 0" range="-0.87267 0.5236" actuatorfrcrange="-50 50"/>
                <geom class="g1_visual" material="g1_metal" mesh="g1_right_ankle_pitch_link"/>
                <geom class="g1_collision" mesh="g1_right_ankle_pitch_link"/>
                <body name="g1_right_ankle_roll_link" pos="0 0 -0.017558">
                  <inertial pos="0.026505 0 -0.016425" quat="0.000481092 0.728482 0.000618967 0.685065" mass="0.608" diaginertia="0.00167218 0.0016161 0.000217621"/>
                  <joint name="g1_right_ankle_roll_joint" pos="0 0 0" axis="1 0 0" range="-0.2618 0.2618" actuatorfrcrange="-50 50"/>
                  <geom class="g1_visual" material="g1_black" mesh="g1_right_ankle_roll_link"/>
                  <geom class="g1_foot" pos="-0.05 0.025 -0.03"/>
                  <geom class="g1_foot" pos="-0.05 -0.025 -0.03"/>
                  <geom class="g1_foot" pos="0.12 0.03 -0.03"/>
                  <geom class="g1_foot" pos="0.12 -0.03 -0.03"/>
                  <site name="g1_right_foot" pos="0 0 0"/>
                </body>
              </body>
            </body>
          </body>
        </body>
      </body>
      <body name="g1_waist_yaw_link">
        <inertial pos="0.003494 0.000233 0.018034" quat="0.289697 0.591001 -0.337795 0.672821" mass="0.214" diaginertia="0.000163531 0.000107714 0.000102205"/>
        <joint name="g1_waist_yaw_joint" pos="0 0 0" axis="0 0 1" range="-2.618 2.618" actuatorfrcrange="-88 88"/>
        <geom class="g1_visual" material="g1_metal" mesh="g1_waist_yaw_link"/>
        <body name="g1_waist_roll_link" pos="-0.0039635 0 0.044">
          <inertial pos="0 2.3e-05 0" quat="0.5 0.5 -0.5 0.5" mass="0.086" diaginertia="8.245e-06 7.079e-06 6.339e-06"/>
          <joint name="g1_waist_roll_joint" pos="0 0 0" axis="1 0 0" range="-0.52 0.52" actuatorfrcrange="-50 50"/>
          <geom class="g1_visual" material="g1_metal" mesh="g1_waist_roll_link"/>
          <body name="g1_torso_link">
            <inertial pos="0.00203158 0.000339683 0.184568" quat="0.999803 -6.03319e-05 0.0198256 0.00131986" mass="7.818" diaginertia="0.121847 0.109825 0.0273735"/>
            <joint name="g1_waist_pitch_joint" pos="0 0 0" axis="0 1 0" range="-0.52 0.52" actuatorfrcrange="-50 50"/>
            <geom class="g1_visual" material="g1_metal" mesh="g1_torso_link"/>
            <geom class="g1_collision" mesh="g1_torso_link"/>
            <geom class="g1_visual" pos="0.0039635 0 -0.044" quat="1 0 0 0" material="g1_black" mesh="g1_logo_link"/>
            <geom class="g1_collision" pos="0.0039635 0 -0.044" quat="1 0 0 0" material="g1_black" mesh="g1_logo_link"/>
            <geom class="g1_visual" pos="0.0039635 0 -0.044" material="g1_black" mesh="g1_head_link"/>
            <geom class="g1_collision" pos="0.0039635 0 -0.044" material="g1_black" mesh="g1_head_link"/>
            <site name="g1_imu_in_torso" pos="-0.03959 -0.00224 0.14792"/>
            <camera name="g1_head_rgb" pos="0.04 0 0.42" quat="0.5 0.5 -0.5 -0.5" fovy="58"/>
            <body name="g1_left_shoulder_pitch_link" pos="0.0039563 0.10022 0.24778" quat="0.990264 0.139201 1.38722e-05 -9.86868e-05">
              <inertial pos="0 0.035892 -0.011628" quat="0.654152 0.0130458 -0.326267 0.68225" mass="0.718" diaginertia="0.000465864 0.000432842 0.000406394"/>
              <joint name="g1_left_shoulder_pitch_joint" pos="0 0 0" axis="0 1 0" range="-3.0892 2.6704" actuatorfrcrange="-25 25"/>
              <geom class="g1_visual" material="g1_metal" mesh="g1_left_shoulder_pitch_link"/>
              <geom class="g1_collision" size="0.03 0.025" pos="0 0.04 -0.01" quat="0.707107 0 0.707107 0" type="cylinder" rgba="0.7 0.7 0.7 1"/>
              <body name="g1_left_shoulder_roll_link" pos="0 0.038 -0.013831" quat="0.990268 -0.139172 0 0">
                <inertial pos="-0.000227 0.00727 -0.063243" quat="0.701256 -0.0196223 -0.00710317 0.712604" mass="0.643" diaginertia="0.000691311 0.000618011 0.000388977"/>
                <joint name="g1_left_shoulder_roll_joint" pos="0 0 0" axis="1 0 0" range="-1.5882 2.2515" actuatorfrcrange="-25 25"/>
                <geom class="g1_visual" material="g1_metal" mesh="g1_left_shoulder_roll_link"/>
                <geom class="g1_collision" size="0.03 0.015" pos="-0.004 0.006 -0.053" type="cylinder" rgba="0.7 0.7 0.7 1"/>
                <body name="g1_left_shoulder_yaw_link" pos="0 0.00624 -0.1032">
                  <inertial pos="0.010773 -0.002949 -0.072009" quat="0.716879 -0.0964829 -0.0679942 0.687134" mass="0.734" diaginertia="0.00106187 0.00103217 0.000400661"/>
                  <joint name="g1_left_shoulder_yaw_joint" pos="0 0 0" axis="0 0 1" range="-2.618 2.618" actuatorfrcrange="-25 25"/>
                  <geom class="g1_visual" material="g1_metal" mesh="g1_left_shoulder_yaw_link"/>
                  <geom class="g1_collision" mesh="g1_left_shoulder_yaw_link"/>
                  <body name="g1_left_elbow_link" pos="0.015783 0 -0.080518">
                    <inertial pos="0.064956 0.004454 -0.010062" quat="0.541765 0.636132 0.388821 0.388129" mass="0.6" diaginertia="0.000443035 0.000421612 0.000259353"/>
                    <joint name="g1_left_elbow_joint" pos="0 0 0" axis="0 1 0" range="-1.0472 2.0944" actuatorfrcrange="-25 25"/>
                    <geom class="g1_visual" material="g1_metal" mesh="g1_left_elbow_link"/>
                    <geom class="g1_collision" mesh="g1_left_elbow_link"/>
                    <body name="g1_left_wrist_roll_link" pos="0.1 0.00188791 -0.01">
                      <inertial pos="0.0171394 0.000537591 4.8864e-07" quat="0.575338 0.411667 -0.574906 0.411094" mass="0.085445" diaginertia="5.48211e-05 4.96646e-05 3.57798e-05"/>
                      <joint name="g1_left_wrist_roll_joint" pos="0 0 0" axis="1 0 0" range="-1.97222 1.97222" actuatorfrcrange="-25 25"/>
                      <geom class="g1_visual" material="g1_metal" mesh="g1_left_wrist_roll_link"/>
                      <geom class="g1_collision" mesh="g1_left_wrist_roll_link"/>
                      <body name="g1_left_wrist_pitch_link" pos="0.038 0 0">
                        <inertial pos="0.0229999 -0.00111685 -0.00111658" quat="0.249998 0.661363 0.293036 0.643608" mass="0.48405" diaginertia="0.000430353 0.000429873 0.000164648"/>
                        <joint name="g1_left_wrist_pitch_joint" pos="0 0 0" axis="0 1 0" range="-1.61443 1.61443" actuatorfrcrange="-5 5"/>
                        <geom class="g1_visual" material="g1_metal" mesh="g1_left_wrist_pitch_link"/>
                        <geom class="g1_collision" mesh="g1_left_wrist_pitch_link"/>
                        <body name="g1_left_wrist_yaw_link" pos="0.046 0 0">
                          <inertial pos="0.0708244 0.000191745 0.00161742" quat="0.510571 0.526295 0.468078 0.493188" mass="0.254576" diaginertia="0.000646113 0.000559993 0.000147566"/>
                          <joint name="g1_left_wrist_yaw_joint" pos="0 0 0" axis="0 0 1" range="-1.61443 1.61443" actuatorfrcrange="-5 5"/>
                          <geom class="g1_visual" material="g1_metal" mesh="g1_left_wrist_yaw_link"/>
                          <geom class="g1_collision" mesh="g1_left_wrist_yaw_link"/>
                          <geom class="g1_visual" pos="0.0415 0.003 0" quat="1 0 0 0" material="g1_metal" mesh="g1_left_rubber_hand"/>
                        </body>
                      </body>
                    </body>
                  </body>
                </body>
              </body>
            </body>
            <body name="g1_right_shoulder_pitch_link" pos="0.0039563 -0.10021 0.24778" quat="0.990264 -0.139201 1.38722e-05 9.86868e-05">
              <inertial pos="0 -0.035892 -0.011628" quat="0.68225 -0.326267 0.0130458 0.654152" mass="0.718" diaginertia="0.000465864 0.000432842 0.000406394"/>
              <joint name="g1_right_shoulder_pitch_joint" pos="0 0 0" axis="0 1 0" range="-3.0892 2.6704" actuatorfrcrange="-25 25"/>
              <geom class="g1_visual" material="g1_metal" mesh="g1_right_shoulder_pitch_link"/>
              <geom class="g1_collision" size="0.03 0.025" pos="0 -0.04 -0.01" quat="0.707107 0 0.707107 0" type="cylinder" rgba="0.7 0.7 0.7 1"/>
              <body name="g1_right_shoulder_roll_link" pos="0 -0.038 -0.013831" quat="0.990268 0.139172 0 0">
                <inertial pos="-0.000227 -0.00727 -0.063243" quat="0.712604 -0.00710317 -0.0196223 0.701256" mass="0.643" diaginertia="0.000691311 0.000618011 0.000388977"/>
                <joint name="g1_right_shoulder_roll_joint" pos="0 0 0" axis="1 0 0" range="-2.2515 1.5882" actuatorfrcrange="-25 25"/>
                <geom class="g1_visual" material="g1_metal" mesh="g1_right_shoulder_roll_link"/>
                <geom class="g1_collision" size="0.03 0.015" pos="-0.004 -0.006 -0.053" type="cylinder" rgba="0.7 0.7 0.7 1"/>
                <body name="g1_right_shoulder_yaw_link" pos="0 -0.00624 -0.1032">
                  <inertial pos="0.010773 0.002949 -0.072009" quat="0.687134 -0.0679942 -0.0964829 0.716879" mass="0.734" diaginertia="0.00106187 0.00103217 0.000400661"/>
                  <joint name="g1_right_shoulder_yaw_joint" pos="0 0 0" axis="0 0 1" range="-2.618 2.618" actuatorfrcrange="-25 25"/>
                  <geom class="g1_visual" material="g1_metal" mesh="g1_right_shoulder_yaw_link"/>
                  <geom class="g1_collision" mesh="g1_right_shoulder_yaw_link"/>
                  <body name="g1_right_elbow_link" pos="0.015783 0 -0.080518">
                    <inertial pos="0.064956 -0.004454 -0.010062" quat="0.388129 0.388821 0.636132 0.541765" mass="0.6" diaginertia="0.000443035 0.000421612 0.000259353"/>
                    <joint name="g1_right_elbow_joint" pos="0 0 0" axis="0 1 0" range="-1.0472 2.0944" actuatorfrcrange="-25 25"/>
                    <geom class="g1_visual" material="g1_metal" mesh="g1_right_elbow_link"/>
                    <geom class="g1_collision" mesh="g1_right_elbow_link"/>
                    <body name="g1_right_wrist_roll_link" pos="0.1 -0.00188791 -0.01">
                      <inertial pos="0.0171394 -0.000537591 4.8864e-07" quat="0.411667 0.575338 -0.411094 0.574906" mass="0.085445" diaginertia="5.48211e-05 4.96646e-05 3.57798e-05"/>
                      <joint name="g1_right_wrist_roll_joint" pos="0 0 0" axis="1 0 0" range="-1.97222 1.97222" actuatorfrcrange="-25 25"/>
                      <geom class="g1_visual" material="g1_metal" mesh="g1_right_wrist_roll_link"/>
                      <geom class="g1_collision" mesh="g1_right_wrist_roll_link"/>
                      <body name="g1_right_wrist_pitch_link" pos="0.038 0 0">
                        <inertial pos="0.0229999 0.00111685 -0.00111658" quat="0.643608 0.293036 0.661363 0.249998" mass="0.48405" diaginertia="0.000430353 0.000429873 0.000164648"/>
                        <joint name="g1_right_wrist_pitch_joint" pos="0 0 0" axis="0 1 0" range="-1.61443 1.61443" actuatorfrcrange="-5 5"/>
                        <geom class="g1_visual" material="g1_metal" mesh="g1_right_wrist_pitch_link"/>
                        <geom class="g1_collision" mesh="g1_right_wrist_pitch_link"/>
                        <body name="g1_right_wrist_yaw_link" pos="0.046 0 0">
                          <inertial pos="0.0708244 -0.000191745 0.00161742" quat="0.493188 0.468078 0.526295 0.510571" mass="0.254576" diaginertia="0.000646113 0.000559993 0.000147566"/>
                          <joint name="g1_right_wrist_yaw_joint" pos="0 0 0" axis="0 0 1" range="-1.61443 1.61443" actuatorfrcrange="-5 5"/>
                          <geom class="g1_visual" material="g1_metal" mesh="g1_right_wrist_yaw_link"/>
                          <geom class="g1_collision" mesh="g1_right_wrist_yaw_link"/>
                          <geom class="g1_visual" pos="0.0415 -0.003 0" quat="1 0 0 0" material="g1_metal" mesh="g1_right_rubber_hand"/>
                        </body>
                      </body>
                    </body>
                  </body>
                </body>
              </body>
            </body>
          </body>
        </body>
      </body>
    </body>
  </worldbody>

  <actuator>
    <general name="g1_left_hip_pitch_joint" class="g1_g1" joint="g1_left_hip_pitch_joint" ctrlrange="-2.5307 2.8798"/>
    <general name="g1_left_hip_roll_joint" class="g1_g1" joint="g1_left_hip_roll_joint" ctrlrange="-0.5236 2.9671"/>
    <general name="g1_left_hip_yaw_joint" class="g1_g1" joint="g1_left_hip_yaw_joint" ctrlrange="-2.7576 2.7576"/>
    <general name="g1_left_knee_joint" class="g1_g1" joint="g1_left_knee_joint" ctrlrange="-0.087267 2.8798"/>
    <general name="g1_left_ankle_pitch_joint" class="g1_g1" joint="g1_left_ankle_pitch_joint" ctrlrange="-0.87267 0.5236"/>
    <general name="g1_left_ankle_roll_joint" class="g1_g1" joint="g1_left_ankle_roll_joint" ctrlrange="-0.2618 0.2618"/>
    <general name="g1_right_hip_pitch_joint" class="g1_g1" joint="g1_right_hip_pitch_joint" ctrlrange="-2.5307 2.8798"/>
    <general name="g1_right_hip_roll_joint" class="g1_g1" joint="g1_right_hip_roll_joint" ctrlrange="-2.9671 0.5236"/>
    <general name="g1_right_hip_yaw_joint" class="g1_g1" joint="g1_right_hip_yaw_joint" ctrlrange="-2.7576 2.7576"/>
    <general name="g1_right_knee_joint" class="g1_g1" joint="g1_right_knee_joint" ctrlrange="-0.087267 2.8798"/>
    <general name="g1_right_ankle_pitch_joint" class="g1_g1" joint="g1_right_ankle_pitch_joint" ctrlrange="-0.87267 0.5236"/>
    <general name="g1_right_ankle_roll_joint" class="g1_g1" joint="g1_right_ankle_roll_joint" ctrlrange="-0.2618 0.2618"/>
    <general name="g1_waist_yaw_joint" class="g1_g1" joint="g1_waist_yaw_joint" ctrlrange="-2.618 2.618"/>
    <general name="g1_waist_roll_joint" class="g1_g1" joint="g1_waist_roll_joint" ctrlrange="-0.52 0.52"/>
    <general name="g1_waist_pitch_joint" class="g1_g1" joint="g1_waist_pitch_joint" ctrlrange="-0.52 0.52"/>
    <general name="g1_left_shoulder_pitch_joint" class="g1_g1" joint="g1_left_shoulder_pitch_joint" ctrlrange="-3.0892 2.6704"/>
    <general name="g1_left_shoulder_roll_joint" class="g1_g1" joint="g1_left_shoulder_roll_joint" ctrlrange="-1.5882 2.2515"/>
    <general name="g1_left_shoulder_yaw_joint" class="g1_g1" joint="g1_left_shoulder_yaw_joint" ctrlrange="-2.618 2.618"/>
    <general name="g1_left_elbow_joint" class="g1_g1" joint="g1_left_elbow_joint" ctrlrange="-1.0472 2.0944"/>
    <general name="g1_left_wrist_roll_joint" class="g1_g1" joint="g1_left_wrist_roll_joint" ctrlrange="-1.97222 1.97222"/>
    <general name="g1_left_wrist_pitch_joint" class="g1_g1" joint="g1_left_wrist_pitch_joint" ctrlrange="-1.61443 1.61443"/>
    <general name="g1_left_wrist_yaw_joint" class="g1_g1" joint="g1_left_wrist_yaw_joint" ctrlrange="-1.61443 1.61443"/>
    <general name="g1_right_shoulder_pitch_joint" class="g1_g1" joint="g1_right_shoulder_pitch_joint" ctrlrange="-3.0892 2.6704"/>
    <general name="g1_right_shoulder_roll_joint" class="g1_g1" joint="g1_right_shoulder_roll_joint" ctrlrange="-2.2515 1.5882"/>
    <general name="g1_right_shoulder_yaw_joint" class="g1_g1" joint="g1_right_shoulder_yaw_joint" ctrlrange="-2.618 2.618"/>
    <general name="g1_right_elbow_joint" class="g1_g1" joint="g1_right_elbow_joint" ctrlrange="-1.0472 2.0944"/>
    <general name="g1_right_wrist_roll_joint" class="g1_g1" joint="g1_right_wrist_roll_joint" ctrlrange="-1.97222 1.97222"/>
    <general name="g1_right_wrist_pitch_joint" class="g1_g1" joint="g1_right_wrist_pitch_joint" ctrlrange="-1.61443 1.61443"/>
    <general name="g1_right_wrist_yaw_joint" class="g1_g1" joint="g1_right_wrist_yaw_joint" ctrlrange="-1.61443 1.61443"/>
  </actuator>

  <sensor>
    <gyro site="g1_imu_in_torso" name="g1_imu-torso-angular-velocity" cutoff="34.9" noise="0.0005"/>
    <accelerometer site="g1_imu_in_torso" name="g1_imu-torso-linear-acceleration" cutoff="157" noise="0.01"/>
    <gyro site="g1_imu_in_pelvis" name="g1_imu-pelvis-angular-velocity" cutoff="34.9" noise="0.0005"/>
    <accelerometer site="g1_imu_in_pelvis" name="g1_imu-pelvis-linear-acceleration" cutoff="157" noise="0.01"/>
  </sensor>

  <keyframe>
    <key name="g1_stand" qpos="10.9 2.78 0.32 1 0 0 0 10.88 3 0.32 1 0 0 0 10.9 3.22 0.32 1 0 0 0 0 0 0.79 1 0 0 0 0 0 0 0 0 0 0 0 0 0 0 0 0 0 0 0.2 0.2 0 1.28 0 0 0 0.2 -0.2 0 1.28 0 0 0" ctrl="0 0 0 0 0 0 0 0 0 0 0 0 0 0 0 0.2 0.2 0 1.28 0 0 0 0.2 -0.2 0 1.28 0 0 0"/>
  </keyframe>
</mujoco>
